Workbook
Name cve_title_1: cve_title!$A$1:$B$164
Name patch_files_info: patch_files_info!$A$1:$G$706
Name relevant_vuln: Vulnerabilities!$A$3:$E$268

Sheet Vulnerabilities
F1: Consolidated
A2: V_ID | B2: Project | C2: CVE | D2: V_CLASSIFICATION | E2: P_COMMIT | F2: Defect Type | G2: Defect Qualifier | H2: # Files | I2: CVE-Title | J2: Tempo | K2: URL | L2: Classified Together | M2: Comments | N2: Filename
A3: vuln635mzl | B3: Mozilla | C3: CVE-2008-0017 | D3: >DenialOfService<>ExecuteCode<>Overflow<>Memorycorruption< | E3: 0ee094d218e6050d34f97eeaac2217faa7c56237 | F3: Checking | G3: Missing | H3: =_xlfn.XLOOKUP(E3,commit_num_files!A$2:A$319,commit_num_files!B$2:B$319) | I3: =_xlfn.XLOOKUP(C3,cve_title!A$2:A$164,cve_title!B$2:B$164) | J3: 20 minutos, 15 primeiros | K3: https://github.com/mozilla/gecko-dev/commit/0ee094d218e6050d34f97eeaac2217faa7c56237 | L3: ok | N3: netwerk/streamconv/converters/nsDirIndexParser.cpp
A4: vuln782mzl | B4: Mozilla | C4: CVE-2009-2662 | D4: >DenialOfService<>ExecuteCode<>Overflow<>Memorycorruption< | E4: 08b448d9dd814dab7889deb0abb13e0f155024f7 | F4: Algorithm/Method | G4: Missing | H4: =_xlfn.XLOOKUP(E4,commit_num_files!A$2:A$319,commit_num_files!B$2:B$319) | I4: =_xlfn.XLOOKUP(C4,cve_title!A$2:A$164,cve_title!B$2:B$164) | K4: https://github.com/mozilla/gecko-dev/commit/08b448d9dd814dab7889deb0abb13e0f155024f7 | L4: ok | N4: js/src/jstracer.cpp
A5: vuln884mzl | B5: Mozilla | C5: CVE-2010-0166 | D5: >DenialOfService<>ExecuteCode<>Overflow<>Memorycorruption< | E5: 6517a01b635b15e935427ac5c23f7ec394cb7bd2 | F5: Algorithm/Method | G5: Incorrect | H5: =_xlfn.XLOOKUP(E5,commit_num_files!A$2:A$319,commit_num_files!B$2:B$319) | I5: =_xlfn.XLOOKUP(C5,cve_title!A$2:A$164,cve_title!B$2:B$164) | K5: https://github.com/mozilla/gecko-dev/commit/6517a01b635b15e935427ac5c23f7ec394cb7bd2 | L5: ok | N5: gfx/thebes/src/gfxFont.cpp
A6: vuln933mzl | B6: Mozilla | C6: CVE-2010-1212 | D6: >DenialOfService<>ExecuteCode<>Overflow<>Memorycorruption< | E6: 35c7952dbd1badc04cd1bb96480676c9077f8805 | F6: Checking | G6: Incorrect | H6: =_xlfn.XLOOKUP(E6,commit_num_files!A$2:A$319,commit_num_files!B$2:B$319) | I6: =_xlfn.XLOOKUP(C6,cve_title!A$2:A$164,cve_title!B$2:B$164) | K6: https://github.com/mozilla/gecko-dev/commit/35c7952dbd1badc04cd1bb96480676c9077f8805 | L6: ok | N6: js/src/jstracer.cpp
A7: vuln944mzl | B7: Mozilla | C7: CVE-2010-1212 | D7: >DenialOfService<>ExecuteCode<>Overflow<>Memorycorruption< | E7: ef586f15354a3dfadda2e65df08bd58558e9efba | F7: Assignment/Initialization | G7: Missing | H7: =_xlfn.XLOOKUP(E7,commit_num_files!A$2:A$319,commit_num_files!B$2:B$319) | I7: =_xlfn.XLOOKUP(C7,cve_title!A$2:A$164,cve_title!B$2:B$164) | K7: https://github.com/mozilla/gecko-dev/commit/ef586f15354a3dfadda2e65df08bd58558e9efba | L7: ok | N7: js/src/jstracer.cpp
A8: vuln944mzl | B8: Mozilla | C8: CVE-2010-1212 | D8: >DenialOfService<>ExecuteCode<>Overflow<>Memorycorruption< | E8: ef586f15354a3dfadda2e65df08bd58558e9efba | F8: Checking | G8: Missing | H8: =_xlfn.XLOOKUP(E8,commit_num_files!A$2:A$319,commit_num_files!B$2:B$319) | I8: =_xlfn.XLOOKUP(C8,cve_title!A$2:A$164,cve_title!B$2:B$164) | K8: https://github.com/mozilla/gecko-dev/commit/ef586f15354a3dfadda2e65df08bd58558e9efba | L8: ok | M8: Another block from the same vulnerability of previous line | N8: js/src/jstracer.cpp
A9: vuln970mzl | B9: Mozilla | C9: CVE-2010-3166 | D9: >ExecuteCode<>Overflow< | E9: e2d46b52f2fa80d20cf89e60372dbca1444ac6ff | F9: Checking | G9: Missing | H9: =_xlfn.XLOOKUP(E9,commit_num_files!A$2:A$319,commit_num_files!B$2:B$319) | I9: =_xlfn.XLOOKUP(C9,cve_title!A$2:A$164,cve_title!B$2:B$164) | K9: https://github.com/mozilla/gecko-dev/commit/e2d46b52f2fa80d20cf89e60372dbca1444ac6ff | L9: ok | N9: layout/base/nsBidiPresUtils.cpp
A10: vuln972mzl | B10: Mozilla | C10: CVE-2010-3168 | D10: >DenialOfService<>ExecuteCode<>Overflow< | E10: 44e12bf078153a8ee665632c44569a4ab7ff1de2 | F10: Assignment/Initialization | G10: Incorrect | H10: =_xlfn.XLOOKUP(E10,commit_num_files!A$2:A$319,commit_num_files!B$2:B$319) | I10: =_xlfn.XLOOKUP(C10,cve_title!A$2:A$164,cve_title!B$2:B$164) | K10: https://github.com/mozilla/gecko-dev/commit/44e12bf078153a8ee665632c44569a4ab7ff1de2 | L10: no | N10: content/xul/templates/src/Makefile.in
A11: vuln972mzl | B11: Mozilla | C11: CVE-2010-3168 | D11: >DenialOfService<>ExecuteCode<>Overflow< | E11: 44e12bf078153a8ee665632c44569a4ab7ff1de2 | F11: Checking | G11: Missing | H11: =_xlfn.XLOOKUP(E11,commit_num_files!A$2:A$319,commit_num_files!B$2:B$319) | I11: =_xlfn.XLOOKUP(C11,cve_title!A$2:A$164,cve_title!B$2:B$164) | K11: https://github.com/mozilla/gecko-dev/commit/44e12bf078153a8ee665632c44569a4ab7ff1de2 | L11: no | N11: content/xul/templates/src/nsXULTreeBuilder.cpp
A12: vuln972mzl | B12: Mozilla | C12: CVE-2010-3168 | D12: >DenialOfService<>ExecuteCode<>Overflow< | E12: 44e12bf078153a8ee665632c44569a4ab7ff1de2 | F12: Checking | G12: Missing | H12: =_xlfn.XLOOKUP(E12,commit_num_files!A$2:A$319,commit_num_files!B$2:B$319) | I12: =_xlfn.XLOOKUP(C12,cve_title!A$2:A$164,cve_title!B$2:B$164) | K12: https://github.com/mozilla/gecko-dev/commit/44e12bf078153a8ee665632c44569a4ab7ff1de2 | L12: no | N12: layout/xul/base/src/tree/src/nsTreeContentView.cpp
A13: vuln972mzl | B13: Mozilla | C13: CVE-2010-3168 | D13: >DenialOfService<>ExecuteCode<>Overflow< | E13: 44e12bf078153a8ee665632c44569a4ab7ff1de2 | F13: Algorithm/Method | G13: Missing | H13: =_xlfn.XLOOKUP(E13,commit_num_files!A$2:A$319,commit_num_files!B$2:B$319) | I13: =_xlfn.XLOOKUP(C13,cve_title!A$2:A$164,cve_title!B$2:B$164) | K13: https://github.com/mozilla/gecko-dev/commit/44e12bf078153a8ee665632c44569a4ab7ff1de2 | L13: no | N13: layout/xul/base/src/tree/public/nsITreeSelection.idl
A14: vuln972mzl | B14: Mozilla | C14: CVE-2010-3168 | D14: >DenialOfService<>ExecuteCode<>Overflow< | E14: 44e12bf078153a8ee665632c44569a4ab7ff1de2 | F14: Algorithm/Method | G14: Missing | H14: =_xlfn.XLOOKUP(E14,commit_num_files!A$2:A$319,commit_num_files!B$2:B$319) | I14: =_xlfn.XLOOKUP(C14,cve_title!A$2:A$164,cve_title!B$2:B$164) | K14: https://github.com/mozilla/gecko-dev/commit/44e12bf078153a8ee665632c44569a4ab7ff1de2 | L14: no | N14: layout/xul/base/src/tree/src/nsTreeContentView.cpp
A15: vuln972mzl | B15: Mozilla | C15: CVE-2010-3168 | D15: >DenialOfService<>ExecuteCode<>Overflow< | E15: 44e12bf078153a8ee665632c44569a4ab7ff1de2 | F15: Algorithm/Method | G15: Missing | H15: =_xlfn.XLOOKUP(E15,commit_num_files!A$2:A$319,commit_num_files!B$2:B$319) | I15: =_xlfn.XLOOKUP(C15,cve_title!A$2:A$164,cve_title!B$2:B$164) | K15: https://github.com/mozilla/gecko-dev/commit/44e12bf078153a8ee665632c44569a4ab7ff1de2 | L15: no | N15: layout/xul/base/src/tree/src/nsTreeContentView.h
A16: vuln972mzl | B16: Mozilla | C16: CVE-2010-3168 | D16: >DenialOfService<>ExecuteCode<>Overflow< | E16: 44e12bf078153a8ee665632c44569a4ab7ff1de2 | F16: Algorithm/Method | G16: Missing | H16: =_xlfn.XLOOKUP(E16,commit_num_files!A$2:A$319,commit_num_files!B$2:B$319) | I16: =_xlfn.XLOOKUP(C16,cve_title!A$2:A$164,cve_title!B$2:B$164) | K16: https://github.com/mozilla/gecko-dev/commit/44e12bf078153a8ee665632c44569a4ab7ff1de2 | L16: no | N16: layout/xul/base/src/tree/src/nsTreeSelection.cpp
A17: vuln972mzl | B17: Mozilla | C17: CVE-2010-3168 | D17: >DenialOfService<>ExecuteCode<>Overflow< | E17: 44e12bf078153a8ee665632c44569a4ab7ff1de2 | F17: Algorithm/Method | G17: Missing | H17: =_xlfn.XLOOKUP(E17,commit_num_files!A$2:A$319,commit_num_files!B$2:B$319) | I17: =_xlfn.XLOOKUP(C17,cve_title!A$2:A$164,cve_title!B$2:B$164) | K17: https://github.com/mozilla/gecko-dev/commit/44e12bf078153a8ee665632c44569a4ab7ff1de2 | L17: no | N17: layout/xul/base/src/tree/src/nsTreeSelection.h
A18: vuln1010mzl | B18: Mozilla | C18: CVE-2010-3778 | D18: >DenialOfService<>ExecuteCode<>Overflow<>Memorycorruption< | E18: a8247109148742d867d85e43f64c85bc0f855e0d | F18: Function | G18: Missing | H18: =_xlfn.XLOOKUP(E18,commit_num_files!A$2:A$319,commit_num_files!B$2:B$319) | I18: =_xlfn.XLOOKUP(C18,cve_title!A$2:A$164,cve_title!B$2:B$164) | K18: https://github.com/mozilla/gecko-dev/commit/a8247109148742d867d85e43f64c85bc0f855e0d | L18: ok | N18: layout/base/nsCSSFrameConstructor.cpp
A19: vuln1010mzl | B19: Mozilla | C19: CVE-2010-3778 | D19: >DenialOfService<>ExecuteCode<>Overflow<>Memorycorruption< | E19: a8247109148742d867d85e43f64c85bc0f855e0d | F19: Algorithm/Method | G19: Incorrect | H19: =_xlfn.XLOOKUP(E19,commit_num_files!A$2:A$319,commit_num_files!B$2:B$319) | I19: =_xlfn.XLOOKUP(C19,cve_title!A$2:A$164,cve_title!B$2:B$164) | K19: https://github.com/mozilla/gecko-dev/commit/a8247109148742d867d85e43f64c85bc0f855e0d | L19: ok | M19: Another block from the same vulnerability of previous line | N19: layout/base/nsCSSFrameConstructor.cpp
A20: vuln1044mzl | B20: Mozilla | C20: CVE-2011-0054 | D20: >ExecuteCode<>Overflow< | E20: 4798ee08d2de3dfa6e972f60ffe305260f915076 | F20: Checking | G20: Incorrect | H20: =_xlfn.XLOOKUP(E20,commit_num_files!A$2:A$319,commit_num_files!B$2:B$319) | I20: =_xlfn.XLOOKUP(C20,cve_title!A$2:A$164,cve_title!B$2:B$164) | K20: https://github.com/mozilla/gecko-dev/commit/4798ee08d2de3dfa6e972f60ffe305260f915076 | L20: ok | N20: js/src/jsemit.cpp
A21: vuln1049mzl | B21: Mozilla | C21: CVE-2011-0061 | D21: >DenialOfService<>ExecuteCode<>Overflow< | E21: 702b90e2aad4199675c3d0d951e00b77cde895ed | F21: Checking | G21: Incorrect | H21: =_xlfn.XLOOKUP(E21,commit_num_files!A$2:A$319,commit_num_files!B$2:B$319) | I21: =_xlfn.XLOOKUP(C21,cve_title!A$2:A$164,cve_title!B$2:B$164) | K21: https://github.com/mozilla/gecko-dev/commit/702b90e2aad4199675c3d0d951e00b77cde895ed | L21: ok | N21: modules/libpr0n/src/RasterImage.cpp
A22: vuln1049mzl | B22: Mozilla | C22: CVE-2011-0061 | D22: >DenialOfService<>ExecuteCode<>Overflow< | E22: 702b90e2aad4199675c3d0d951e00b77cde895ed | F22: Checking | G22: Missing | H22: =_xlfn.XLOOKUP(E22,commit_num_files!A$2:A$319,commit_num_files!B$2:B$319) | I22: =_xlfn.XLOOKUP(C22,cve_title!A$2:A$164,cve_title!B$2:B$164) | K22: https://github.com/mozilla/gecko-dev/commit/702b90e2aad4199675c3d0d951e00b77cde895ed | L22: ok | N22: modules/libpr0n/src/RasterImage.cpp
A23: vuln1106mzl | B23: Mozilla | C23: CVE-2011-2377 | D23: >DenialOfService<>ExecuteCode<>Overflow<>Memorycorruption< | E23: 0f63056d1e8fdffd91e186e87d1fa153823b51cf | F23: Checking | G23: Missing | H23: =_xlfn.XLOOKUP(E23,commit_num_files!A$2:A$319,commit_num_files!B$2:B$319) | I23: =_xlfn.XLOOKUP(C23,cve_title!A$2:A$164,cve_title!B$2:B$164) | K23: https://github.com/mozilla/gecko-dev/commit/0f63056d1e8fdffd91e186e87d1fa153823b51cf | L23: no | N23: modules/libpr0n/decoders/nsBMPDecoder.cpp
A24: vuln1106mzl | B24: Mozilla | C24: CVE-2011-2377 | D24: >DenialOfService<>ExecuteCode<>Overflow<>Memorycorruption< | E24: 0f63056d1e8fdffd91e186e87d1fa153823b51cf | F24: Checking | G24: Missing | H24: =_xlfn.XLOOKUP(E24,commit_num_files!A$2:A$319,commit_num_files!B$2:B$319) | I24: =_xlfn.XLOOKUP(C24,cve_title!A$2:A$164,cve_title!B$2:B$164) | K24: https://github.com/mozilla/gecko-dev/commit/0f63056d1e8fdffd91e186e87d1fa153823b51cf | L24: no | N24: modules/libpr0n/decoders/nsGIFDecoder2.cpp
A25: vuln1106mzl | B25: Mozilla | C25: CVE-2011-2377 | D25: >DenialOfService<>ExecuteCode<>Overflow<>Memorycorruption< | E25: 0f63056d1e8fdffd91e186e87d1fa153823b51cf | F25: Checking | G25: Missing | H25: =_xlfn.XLOOKUP(E25,commit_num_files!A$2:A$319,commit_num_files!B$2:B$319) | I25: =_xlfn.XLOOKUP(C25,cve_title!A$2:A$164,cve_title!B$2:B$164) | K25: https://github.com/mozilla/gecko-dev/commit/0f63056d1e8fdffd91e186e87d1fa153823b51cf | L25: no | N25: modules/libpr0n/decoders/nsIconDecoder.cpp
A26: vuln1106mzl | B26: Mozilla | C26: CVE-2011-2377 | D26: >DenialOfService<>ExecuteCode<>Overflow<>Memorycorruption< | E26: 0f63056d1e8fdffd91e186e87d1fa153823b51cf | F26: Checking | G26: Missing | H26: =_xlfn.XLOOKUP(E26,commit_num_files!A$2:A$319,commit_num_files!B$2:B$319) | I26: =_xlfn.XLOOKUP(C26,cve_title!A$2:A$164,cve_title!B$2:B$164) | K26: https://github.com/mozilla/gecko-dev/commit/0f63056d1e8fdffd91e186e87d1fa153823b51cf | L26: no | N26: modules/libpr0n/decoders/nsJPEGDecoder.cpp
A27: vuln1106mzl | B27: Mozilla | C27: CVE-2011-2377 | D27: >DenialOfService<>ExecuteCode<>Overflow<>Memorycorruption< | E27: 0f63056d1e8fdffd91e186e87d1fa153823b51cf | F27: Checking | G27: Missing | H27: =_xlfn.XLOOKUP(E27,commit_num_files!A$2:A$319,commit_num_files!B$2:B$319) | I27: =_xlfn.XLOOKUP(C27,cve_title!A$2:A$164,cve_title!B$2:B$164) | K27: https://github.com/mozilla/gecko-dev/commit/0f63056d1e8fdffd91e186e87d1fa153823b51cf | L27: no | N27: modules/libpr0n/decoders/nsPNGDecoder.cpp
A28: vuln1106mzl | B28: Mozilla | C28: CVE-2011-2377 | D28: >DenialOfService<>ExecuteCode<>Overflow<>Memorycorruption< | E28: 0f63056d1e8fdffd91e186e87d1fa153823b51cf | F28: Checking | G28: Incorrect | H28: =_xlfn.XLOOKUP(E28,commit_num_files!A$2:A$319,commit_num_files!B$2:B$319) | I28: =_xlfn.XLOOKUP(C28,cve_title!A$2:A$164,cve_title!B$2:B$164) | K28: https://github.com/mozilla/gecko-dev/commit/0f63056d1e8fdffd91e186e87d1fa153823b51cf | L28: no | N28: modules/libpr0n/src/Decoder.h
A29: vuln1106mzl | B29: Mozilla | C29: CVE-2011-2377 | D29: >DenialOfService<>ExecuteCode<>Overflow<>Memorycorruption< | E29: 0f63056d1e8fdffd91e186e87d1fa153823b51cf | F29: Algorithm/Method | G29: Incorrect | H29: =_xlfn.XLOOKUP(E29,commit_num_files!A$2:A$319,commit_num_files!B$2:B$319) | I29: =_xlfn.XLOOKUP(C29,cve_title!A$2:A$164,cve_title!B$2:B$164) | K29: https://github.com/mozilla/gecko-dev/commit/0f63056d1e8fdffd91e186e87d1fa153823b51cf | L29: no | M29: It has assignment-missing, assignment-incorrect, checking-missing. | N29: modules/libpr0n/src/RasterImage.cpp
A30: vuln1244mzl | B30: Mozilla | C30: CVE-2011-3002 | D30: >DenialOfService<>ExecuteCode<>Overflow< | E30: 6d8c3d6fdc3764024da2df6b474760ce3a0a5337 | F30: Assignment/Initialization | G30: Missing | H30: =_xlfn.XLOOKUP(E30,commit_num_files!A$2:A$319,commit_num_files!B$2:B$319) | I30: =_xlfn.XLOOKUP(C30,cve_title!A$2:A$164,cve_title!B$2:B$164) | K30: https://github.com/mozilla/gecko-dev/commit/6d8c3d6fdc3764024da2df6b474760ce3a0a5337 | L30: no | N30: gfx/angle/Makefile.in
A31: vuln1244mzl | B31: Mozilla | C31: CVE-2011-3002 | D31: >DenialOfService<>ExecuteCode<>Overflow< | E31: 6d8c3d6fdc3764024da2df6b474760ce3a0a5337 | F31: Assignment/Initialization | G31: Missing | H31: =_xlfn.XLOOKUP(E31,commit_num_files!A$2:A$319,commit_num_files!B$2:B$319) | I31: =_xlfn.XLOOKUP(C31,cve_title!A$2:A$164,cve_title!B$2:B$164) | K31: https://github.com/mozilla/gecko-dev/commit/6d8c3d6fdc3764024da2df6b474760ce3a0a5337 | L31: no | N31: gfx/angle/src/libEGL/Makefile.in
A32: vuln1244mzl | B32: Mozilla | C32: CVE-2011-3002 | D32: >DenialOfService<>ExecuteCode<>Overflow< | E32: 6d8c3d6fdc3764024da2df6b474760ce3a0a5337 | F32: Assignment/Initialization | G32: Missing | H32: =_xlfn.XLOOKUP(E32,commit_num_files!A$2:A$319,commit_num_files!B$2:B$319) | I32: =_xlfn.XLOOKUP(C32,cve_title!A$2:A$164,cve_title!B$2:B$164) | K32: https://github.com/mozilla/gecko-dev/commit/6d8c3d6fdc3764024da2df6b474760ce3a0a5337 | L32: no | N32: gfx/angle/src/libGLESv2/Makefile.in
A33: vuln1244mzl | B33: Mozilla | C33: CVE-2011-3002 | D33: >DenialOfService<>ExecuteCode<>Overflow< | E33: 6d8c3d6fdc3764024da2df6b474760ce3a0a5337 | F33: Checking | G33: Extraneous | H33: =_xlfn.XLOOKUP(E33,commit_num_files!A$2:A$319,commit_num_files!B$2:B$319) | I33: =_xlfn.XLOOKUP(C33,cve_title!A$2:A$164,cve_title!B$2:B$164) | K33: https://github.com/mozilla/gecko-dev/commit/6d8c3d6fdc3764024da2df6b474760ce3a0a5337 | L33: no | N33: gfx/angle/src/compiler/preprocessor/atom.c
A34: vuln1245mzl | B34: Mozilla | C34: CVE-2011-3003 | D34: >DenialOfService<>ExecuteCode<>Overflow< | E34: 5dae9ec03ce9a864a8d07f73814980e20f2da305 | F34: Assignment/Initialization | G34: Missing | H34: =_xlfn.XLOOKUP(E34,commit_num_files!A$2:A$319,commit_num_files!B$2:B$319) | I34: =_xlfn.XLOOKUP(C34,cve_title!A$2:A$164,cve_title!B$2:B$164) | K34: https://github.com/mozilla/gecko-dev/commit/5dae9ec03ce9a864a8d07f73814980e20f2da305 | L34: ok | N34: content/canvas/src/WebGLContext.h
A35: vuln1245mzl | B35: Mozilla | C35: CVE-2011-3003 | D35: >DenialOfService<>ExecuteCode<>Overflow< | E35: 5dae9ec03ce9a864a8d07f73814980e20f2da305 | F35: Checking | G35: Incorrect | H35: =_xlfn.XLOOKUP(E35,commit_num_files!A$2:A$319,commit_num_files!B$2:B$319) | I35: =_xlfn.XLOOKUP(C35,cve_title!A$2:A$164,cve_title!B$2:B$164) | K35: https://github.com/mozilla/gecko-dev/commit/5dae9ec03ce9a864a8d07f73814980e20f2da305 | L35: ok | M35: Another block from the same vulnerability of previous line | N35: content/canvas/src/WebGLContext.h
A36: vuln1249mzl | B36: Mozilla | C36: CVE-2011-3005 | D36: >DenialOfService<>ExecuteCode<>Overflow< | E36: 7334d9a749078e9e7e6a2e42dba341b7728b06cd | F36: Algorithm/Method | G36: Incorrect | H36: =_xlfn.XLOOKUP(E36,commit_num_files!A$2:A$319,commit_num_files!B$2:B$319) | I36: =_xlfn.XLOOKUP(C36,cve_title!A$2:A$164,cve_title!B$2:B$164) | K36: https://github.com/mozilla/gecko-dev/commit/7334d9a749078e9e7e6a2e42dba341b7728b06cd | L36: no | N36: content/media/ogg/nsOggReader.cpp
A37: vuln1249mzl | B37: Mozilla | C37: CVE-2011-3005 | D37: >DenialOfService<>ExecuteCode<>Overflow< | E37: 7334d9a749078e9e7e6a2e42dba341b7728b06cd | F37: Assignment/Initialization | G37: Incorrect | H37: =_xlfn.XLOOKUP(E37,commit_num_files!A$2:A$319,commit_num_files!B$2:B$319) | I37: =_xlfn.XLOOKUP(C37,cve_title!A$2:A$164,cve_title!B$2:B$164) | K37: https://github.com/mozilla/gecko-dev/commit/7334d9a749078e9e7e6a2e42dba341b7728b06cd | L37: no | N37: content/media/test/Makefile.in
A38: vuln1249mzl | B38: Mozilla | C38: CVE-2011-3005 | D38: >DenialOfService<>ExecuteCode<>Overflow< | E38: 7334d9a749078e9e7e6a2e42dba341b7728b06cd | F38: Assignment/Initialization | G38: Incorrect | H38: =_xlfn.XLOOKUP(E38,commit_num_files!A$2:A$319,commit_num_files!B$2:B$319) | I38: =_xlfn.XLOOKUP(C38,cve_title!A$2:A$164,cve_title!B$2:B$164) | K38: https://github.com/mozilla/gecko-dev/commit/7334d9a749078e9e7e6a2e42dba341b7728b06cd | L38: no | N38: content/media/test/manifest.js
A39: vuln1249mzl | B39: Mozilla | C39: CVE-2011-3005 | D39: >DenialOfService<>ExecuteCode<>Overflow< | E39: 7334d9a749078e9e7e6a2e42dba341b7728b06cd | F39: Assignment/Initialization | G39: Incorrect | H39: =_xlfn.XLOOKUP(E39,commit_num_files!A$2:A$319,commit_num_files!B$2:B$319) | I39: =_xlfn.XLOOKUP(C39,cve_title!A$2:A$164,cve_title!B$2:B$164) | K39: https://github.com/mozilla/gecko-dev/commit/7334d9a749078e9e7e6a2e42dba341b7728b06cd | L39: no | N39: content/media/test/multiple-bos.ogg
A40: vuln1266mzl | B40: Mozilla | C40: CVE-2011-3650 | D40: >DenialOfService<>Overflow<>Memorycorruption< | E40: a16a44393d62c68c5aded9e6e282c5ac4fb3e496 | F40: Assignment/Initialization | G40: Incorrect | H40: =_xlfn.XLOOKUP(E40,commit_num_files!A$2:A$319,commit_num_files!B$2:B$319) | I40: =_xlfn.XLOOKUP(C40,cve_title!A$2:A$164,cve_title!B$2:B$164) | K40: https://github.com/mozilla/gecko-dev/commit/a16a44393d62c68c5aded9e6e282c5ac4fb3e496 | L40: no | N40: js/src/jsinterp.cpp
...

Sheet ODC-PivotTable
A3: Contagem de Defect Type | B3: Rótulos de Coluna
A4: Rótulos de Linha | B4: Incorrect | C4: Missing | D4: Extraneous | E4: (em branco) | F4: Total Geral | H4: Incorrect | I4: Missing | J4: Extraneous
A5: Assignment/Initiatialization | B5: 24 | C5: 18 | F5: 42 | G5: Assignment/Initiatialization | H5: =GETPIVOTDATA("Defect Type",$A$3,"Defect Type",$G5,"Defect Qualifier",H$4)/GETPIVOTDATA("Defect Type",$A$3) | I5: =GETPIVOTDATA("Defect Type",$A$3,"Defect Type",$G5,"Defect Qualifier",I$4)/GETPIVOTDATA("Defect Type",$A$3) | J5: =GETPIVOTDATA("Defect Type",$A$3,"Defect Type",$G5,"Defect Qualifier",J$4)/GETPIVOTDATA("Defect Type",$A$3) | K5: =GETPIVOTDATA("Defect Type",$A$3,"Defect Type",G5)/GETPIVOTDATA("Defect Type",$A$3)
A6: Checking | B6: 31 | C6: 51 | D6: 3 | F6: 85 | G6: Checking | H6: =GETPIVOTDATA("Defect Type",$A$3,"Defect Type",$G6,"Defect Qualifier",H$4)/GETPIVOTDATA("Defect Type",$A$3) | I6: =GETPIVOTDATA("Defect Type",$A$3,"Defect Type",$G6,"Defect Qualifier",I$4)/GETPIVOTDATA("Defect Type",$A$3) | J6: =GETPIVOTDATA("Defect Type",$A$3,"Defect Type",$G6,"Defect Qualifier",J$4)/GETPIVOTDATA("Defect Type",$A$3) | K6: =GETPIVOTDATA("Defect Type",$A$3,"Defect Type",G6)/GETPIVOTDATA("Defect Type",$A$3)
A7: Algorithm/Method | B7: 50 | C7: 12 | D7: 2 | F7: 64 | G7: Algorithm/Method | H7: =GETPIVOTDATA("Defect Type",$A$3,"Defect Type",$G7,"Defect Qualifier",H$4)/GETPIVOTDATA("Defect Type",$A$3) | I7: =GETPIVOTDATA("Defect Type",$A$3,"Defect Type",$G7,"Defect Qualifier",I$4)/GETPIVOTDATA("Defect Type",$A$3) | J7: =GETPIVOTDATA("Defect Type",$A$3,"Defect Type",$G7,"Defect Qualifier",J$4)/GETPIVOTDATA("Defect Type",$A$3) | K7: =GETPIVOTDATA("Defect Type",$A$3,"Defect Type",G7)/GETPIVOTDATA("Defect Type",$A$3)
A8: Function | B8: 2 | C8: 4 | F8: 6 | G8: Function | H8: =GETPIVOTDATA("Defect Type",$A$3,"Defect Type",$G8,"Defect Qualifier",H$4)/GETPIVOTDATA("Defect Type",$A$3) | I8: =GETPIVOTDATA("Defect Type",$A$3,"Defect Type",$G8,"Defect Qualifier",I$4)/GETPIVOTDATA("Defect Type",$A$3) | J8: =GETPIVOTDATA("Defect Type",$A$3,"Defect Type",$G8,"Defect Qualifier",J$4)/GETPIVOTDATA("Defect Type",$A$3) | K8: =GETPIVOTDATA("Defect Type",$A$3,"Defect Type",G8)/GETPIVOTDATA("Defect Type",$A$3)
A9: Interface | B9: 16 | C9: 3 | F9: 19 | G9: Interface | H9: =GETPIVOTDATA("Defect Type",$A$3,"Defect Type",$G9,"Defect Qualifier",H$4)/GETPIVOTDATA("Defect Type",$A$3) | I9: =GETPIVOTDATA("Defect Type",$A$3,"Defect Type",$G9,"Defect Qualifier",I$4)/GETPIVOTDATA("Defect Type",$A$3) | J9: =GETPIVOTDATA("Defect Type",$A$3,"Defect Type",$G9,"Defect Qualifier",J$4)/GETPIVOTDATA("Defect Type",$A$3) | K9: =GETPIVOTDATA("Defect Type",$A$3,"Defect Type",G9)/GETPIVOTDATA("Defect Type",$A$3)
A10: (em branco)
A11: Total Geral | B11: 123 | C11: 88 | D11: 5 | F11: 216 | H11: =GETPIVOTDATA("Defect Type",$A$3,"Defect Qualifier","Incorrect")/GETPIVOTDATA("Defect Type",$A$3) | I11: =GETPIVOTDATA("Defect Type",$A$3,"Defect Qualifier","Missing")/GETPIVOTDATA("Defect Type",$A$3) | J11: =GETPIVOTDATA("Defect Type",$A$3,"Defect Qualifier","Extraneous")/GETPIVOTDATA("Defect Type",$A$3)
A21: Contagem de Defect Type | B21: Rótulos de Coluna
A22: Rótulos de Linha | B22: Linux | C22: Mozilla | D22: Xen | E22: (em branco) | F22: Total Geral | H22: Linux | I22: Mozilla | J22: Xen
A23: Checking | B23: 45 | C23: 39 | D23: 1 | F23: 85 | G23: Checking | H23: =GETPIVOTDATA("Defect Type",$A$21,"Project",H$22,"Defect Type",$G23)/GETPIVOTDATA("Defect Type",$A$21,"Project",H$22) | I23: =GETPIVOTDATA("Defect Type",$A$21,"Project",I$22,"Defect Type",$G23)/GETPIVOTDATA("Defect Type",$A$21,"Project",I$22) | J23: =GETPIVOTDATA("Defect Type",$A$21,"Project",J$22,"Defect Type",$G23)/GETPIVOTDATA("Defect Type",$A$21,"Project",J$22)
A24: Algorithm/Method | B24: 33 | C24: 27 | D24: 4 | F24: 64 | G24: Algorithm/Method | H24: =GETPIVOTDATA("Defect Type",$A$21,"Project",H$22,"Defect Type",$G24)/GETPIVOTDATA("Defect Type",$A$21,"Project",H$22) | I24: =GETPIVOTDATA("Defect Type",$A$21,"Project",I$22,"Defect Type",$G24)/GETPIVOTDATA("Defect Type",$A$21,"Project",I$22) | J24: =GETPIVOTDATA("Defect Type",$A$21,"Project",J$22,"Defect Type",$G24)/GETPIVOTDATA("Defect Type",$A$21,"Project",J$22)
A25: Assignment/Initiatialization | B25: 27 | C25: 15 | F25: 42 | G25: Assignment/Initiatialization | H25: =GETPIVOTDATA("Defect Type",$A$21,"Project",H$22,"Defect Type",$G25)/GETPIVOTDATA("Defect Type",$A$21,"Project",H$22) | I25: =GETPIVOTDATA("Defect Type",$A$21,"Project",I$22,"Defect Type",$G25)/GETPIVOTDATA("Defect Type",$A$21,"Project",I$22) | J25: =GETPIVOTDATA("Defect Type",$A$21,"Project",J$22,"Defect Type",$G25)/GETPIVOTDATA("Defect Type",$A$21,"Project",J$22)
A26: Interface | B26: 11 | C26: 8 | F26: 19 | G26: Interface | H26: =GETPIVOTDATA("Defect Type",$A$21,"Project",H$22,"Defect Type",$G26)/GETPIVOTDATA("Defect Type",$A$21,"Project",H$22) | I26: =GETPIVOTDATA("Defect Type",$A$21,"Project",I$22,"Defect Type",$G26)/GETPIVOTDATA("Defect Type",$A$21,"Project",I$22) | J26: =GETPIVOTDATA("Defect Type",$A$21,"Project",J$22,"Defect Type",$G26)/GETPIVOTDATA("Defect Type",$A$21,"Project",J$22)
A27: Function | B27: 4 | C27: 2 | F27: 6 | G27: Function | H27: =GETPIVOTDATA("Defect Type",$A$21,"Project",H$22,"Defect Type",$G27)/GETPIVOTDATA("Defect Type",$A$21,"Project",H$22) | I27: =GETPIVOTDATA("Defect Type",$A$21,"Project",I$22,"Defect Type",$G27)/GETPIVOTDATA("Defect Type",$A$21,"Project",I$22) | J27: =GETPIVOTDATA("Defect Type",$A$21,"Project",J$22,"Defect Type",$G27)/GETPIVOTDATA("Defect Type",$A$21,"Project",J$22)
A28: (em branco)
A29: Total Geral | B29: 120 | C29: 91 | D29: 5 | F29: 216 | H29: =SUM(H23:H27) | I29: =SUM(I23:I27) | J29: =SUM(J23:J27)
A34: Contagem de Defect Qualifier | B34: Rótulos de Coluna
A35: Rótulos de Linha | B35: Linux | C35: Mozilla | D35: Xen | E35: (em branco) | F35: Total Geral | H35: =B35 | I35: =C35 | J35: =D35
A36: Incorrect | B36: 74 | C36: 46 | D36: 3 | F36: 123 | G36: =A36 | H36: =GETPIVOTDATA("Defect Qualifier",$A$34,"Project",H$35,"Defect Qualifier",$G36)/GETPIVOTDATA("Defect Qualifier",$A$34,"Project",H$35) | I36: =GETPIVOTDATA("Defect Qualifier",$A$34,"Project",I$35,"Defect Qualifier",$G36)/GETPIVOTDATA("Defect Qualifier",$A$34,"Project",I$35) | J36: =GETPIVOTDATA("Defect Qualifier",$A$34,"Project",J$35,"Defect Qualifier",$G36)/GETPIVOTDATA("Defect Qualifier",$A$34,"Project",J$35)
A37: Missing | B37: 45 | C37: 42 | D37: 1 | F37: 88 | G37: =A37 | H37: =GETPIVOTDATA("Defect Qualifier",$A$34,"Project",H$35,"Defect Qualifier",$G37)/GETPIVOTDATA("Defect Qualifier",$A$34,"Project",H$35) | I37: =GETPIVOTDATA("Defect Qualifier",$A$34,"Project",I$35,"Defect Qualifier",$G37)/GETPIVOTDATA("Defect Qualifier",$A$34,"Project",I$35) | J37: =GETPIVOTDATA("Defect Qualifier",$A$34,"Project",J$35,"Defect Qualifier",$G37)/GETPIVOTDATA("Defect Qualifier",$A$34,"Project",J$35)
A38: Extraneous | B38: 1 | C38: 3 | D38: 1 | F38: 5 | G38: =A38 | H38: =GETPIVOTDATA("Defect Qualifier",$A$34,"Project",H$35,"Defect Qualifier",$G38)/GETPIVOTDATA("Defect Qualifier",$A$34,"Project",H$35) | I38: =GETPIVOTDATA("Defect Qualifier",$A$34,"Project",I$35,"Defect Qualifier",$G38)/GETPIVOTDATA("Defect Qualifier",$A$34,"Project",I$35) | J38: =GETPIVOTDATA("Defect Qualifier",$A$34,"Project",J$35,"Defect Qualifier",$G38)/GETPIVOTDATA("Defect Qualifier",$A$34,"Project",J$35)
A39: (em branco)
A40: Total Geral | B40: 120 | C40: 91 | D40: 5 | F40: 216 | H40: =SUM(H36:H38) | I40: =SUM(I36:I38) | J40: =SUM(J36:J38)

Sheet Definitions
A1: Defect Type
A2: Assignment/Initialization | C2: * | F2: *: these are the options listed in ﻿Morrison2018
A3: Checking | C3: *
A4: Timing
A5: Algorithm/Method | C5: *
A6: Function
A7: Interface
A10: Defect Qualifier
A11: Missing
A12: Incorrect
A13: Extraneous | B13: (removing unnecessary code)

Sheet patch_files_info
A1: repository | B1: commit | C1: filename | D1: additions | E1: deletions | F1: changes | G1: status
A2: 1 | B2: 004dd20c078c42719f22f92c0d4356c240ff7595 | C2: netwerk/protocol/websocket/WebSocketChannel.cpp | D2: 4 | E2: 0 | F2: 4 | G2: modified
A3: 1 | B3: 018237816e6732154e0bfeed836ca8a2bcc5c83e | C3: js/src/builtin/TypedObject.cpp | D3: 2 | E3: 2 | F3: 4 | G3: modified
A4: 1 | B4: 018237816e6732154e0bfeed836ca8a2bcc5c83e | C4: js/src/builtin/TypedObject.h | D4: 1 | E4: 1 | F4: 2 | G4: modified
A5: 1 | B5: 018237816e6732154e0bfeed836ca8a2bcc5c83e | C5: js/src/vm/ArrayBufferObject.cpp | D5: 24 | E5: 30 | F5: 54 | G5: modified
A6: 1 | B6: 018237816e6732154e0bfeed836ca8a2bcc5c83e | C6: js/src/vm/ArrayBufferObject.h | D6: 4 | E6: 9 | F6: 13 | G6: modified
A7: 1 | B7: 018237816e6732154e0bfeed836ca8a2bcc5c83e | C7: js/src/vm/TypedArrayObject.cpp | D7: 4 | E7: 4 | F7: 8 | G7: modified
A8: 1 | B8: 018237816e6732154e0bfeed836ca8a2bcc5c83e | C8: js/src/vm/TypedArrayObject.h | D8: 2 | E8: 2 | F8: 4 | G8: modified
A9: 1 | B9: 027b891ee8735e38a77da3a307b832323b93a1ea | C9: content/base/src/nsContentSink.cpp | D9: 2 | E9: 1 | F9: 3 | G9: modified
A10: 1 | B10: 027b891ee8735e38a77da3a307b832323b93a1ea | C10: docshell/base/nsDocShell.cpp | D10: 4 | E10: 2 | F10: 6 | G10: modified
A11: 1 | B11: 050414e94b197bc129065b587755848625a2443f | C11: layout/generic/nsContainerFrame.cpp | D11: 48 | E11: 2 | F11: 50 | G11: modified
A12: 1 | B12: 0556e96340b92579b3714b0e81f589b6be6ed260 | C12: hal/windows/WindowsGamepad.cpp | D12: 23 | E12: 6 | F12: 29 | G12: modified
A13: 1 | B13: 085004cc6a7b6741743a39949d192049fbc4bc9c | C13: content/svg/content/src/nsDOMSVGZoomEvent.cpp | D13: 2 | E13: 0 | F13: 2 | G13: modified
... A706: 3 | B706: f8bdc889ce8e8fe85e6a9f94922d30d765546e72 | C706: xen/include/asm-x86/mm.h | D706: 1 | E706: 0 | F706: 1 | G706: modified

Sheet patch_files_info_pt
A3: Contagem de filename | B3: Rótulos de Coluna
A4: Rótulos de Linha | B4: 1 | C4: Total Geral
A5: 004dd20c078c42719f22f92c0d4356c240ff7595 | B5: 1 | C5: 1
A6: ff9650ba8d901c3370643329857c973276d467d5 | B6: 1 | C6: 1
A7: 7daf7f3676c49a2f1360a98933b80684ab4e431d | B7: 1 | C7: 1
A8: 050414e94b197bc129065b587755848625a2443f | B8: 1 | C8: 1
A9: 702b90e2aad4199675c3d0d951e00b77cde895ed | B9: 1 | C9: 1
A10: fcfb3ebfa23ac631c7873daf085c280c4b3f6017 | B10: 1 | C10: 1
A11: 73da110d58e3c70e0faacad75af7fc66ef935cb4 | B11: 1 | C11: 1
A12: 0e7b37595e53656c530d71a5866366307cccc04f | B12: 1 | C12: 1
A13: 7893caea6b672bed561eddb538210fe3623bea75 | B13: 1 | C13: 1
A14: 10fe38e01faa728edc09d19dc76e28f5c1230705 | B14: 1 | C14: 1
A15: 0556e96340b92579b3714b0e81f589b6be6ed260 | B15: 1 | C15: 1
A16: 19af9d4ec00170ae7aa9c6a4d8ff395232fc1628 | B16: 1 | C16: 1
... A176: Total Geral | B176: 451 | C176: 451

Sheet commit_num_files
A1: P_COMMIT | B1: NUM_FILES
A2: 004dd20c078c42719f22f92c0d4356c240ff7595 | B2: 1
A3: ff9650ba8d901c3370643329857c973276d467d5 | B3: 1
A4: 7daf7f3676c49a2f1360a98933b80684ab4e431d | B4: 1
A5: 050414e94b197bc129065b587755848625a2443f | B5: 1
A6: 702b90e2aad4199675c3d0d951e00b77cde895ed | B6: 1
A7: fcfb3ebfa23ac631c7873daf085c280c4b3f6017 | B7: 1
A8: 73da110d58e3c70e0faacad75af7fc66ef935cb4 | B8: 1
A9: 0e7b37595e53656c530d71a5866366307cccc04f | B9: 1
A10: 7893caea6b672bed561eddb538210fe3623bea75 | B10: 1
A11: 10fe38e01faa728edc09d19dc76e28f5c1230705 | B11: 1
A12: 0556e96340b92579b3714b0e81f589b6be6ed260 | B12: 1
A13: 19af9d4ec00170ae7aa9c6a4d8ff395232fc1628 | B13: 1
... A319: 4939f9a6dee4280f38730fd3066e5dce353112f6 | B319: 10

Sheet cve_title
A1: cve | B1: cve_title
A2: CVE-2008-0017 | B2: The http-index-format MIME type parser (nsDirIndexParser) in Firefox 3.x before 3.0.4, Firefox 2.x before 2.0.0.18, and SeaMonkey 1.x before 1.1.13 does not check for an allocation failure, which allows remote attackers to cause a denial of service (crash) and possibly execute arbitrary code via an HTTP index response with a crafted 200 header, which triggers memory corruption and a buffer overflow.
A3: CVE-2009-2662 | B3: The browser engine in Mozilla Firefox 3.5.x before 3.5.2 allows remote attackers to cause a denial of service (memory corruption and application crash) or possibly execute arbitrary code via vectors related to the TraceRecorder::snapshot function in js/src/jstracer.cpp, and unspecified other vectors.
A4: CVE-2010-0166 | B4: The gfxTextRun::SanitizeGlyphRuns function in gfx/thebes/src/gfxFont.cpp in the browser engine in Mozilla Firefox 3.6 before 3.6.2 on Mac OS X, when the Core Text API is used, does not properly perform certain deletions, which allows remote attackers to cause a denial of service (memory corruption and application crash) and possibly execute arbitrary code via an HTML document containing invisible Unicode characters, as demonstrated by the U+FEFF, U+FFF9, U+FFFA, and U+FFFB characters.
A5: CVE-2010-1212 | B5: js/src/jstracer.cpp in the browser engine in Mozilla Firefox 3.6.x before 3.6.7 and Thunderbird 3.1.x before 3.1.1 allows remote attackers to cause a denial of service (memory corruption and application crash) or possibly execute arbitrary code via vectors related to (1) propagation of deep aborts in the TraceRecorder::record_JSOP_BINDNAME function, (2) depth handling in the TraceRecorder::record_JSOP_GETELEM function, and (3) tracing of out-of-range arguments in the TraceRecorder::record_JSOP_ARGSUB function.
A6: CVE-2010-1212 | B6: js/src/jstracer.cpp in the browser engine in Mozilla Firefox 3.6.x before 3.6.7 and Thunderbird 3.1.x before 3.1.1 allows remote attackers to cause a denial of service (memory corruption and application crash) or possibly execute arbitrary code via vectors related to (1) propagation of deep aborts in the TraceRecorder::record_JSOP_BINDNAME function, (2) depth handling in the TraceRecorder::record_JSOP_GETELEM function, and (3) tracing of out-of-range arguments in the TraceRecorder::record_JSOP_ARGSUB function.
A7: CVE-2010-1212 | B7: js/src/jstracer.cpp in the browser engine in Mozilla Firefox 3.6.x before 3.6.7 and Thunderbird 3.1.x before 3.1.1 allows remote attackers to cause a denial of service (memory corruption and application crash) or possibly execute arbitrary code via vectors related to (1) propagation of deep aborts in the TraceRecorder::record_JSOP_BINDNAME function, (2) depth handling in the TraceRecorder::record_JSOP_GETELEM function, and (3) tracing of out-of-range arguments in the TraceRecorder::record_JSOP_ARGSUB function.
A8: CVE-2010-3166 | B8: Heap-based buffer overflow in the nsTextFrameUtils::TransformText function in Mozilla Firefox before 3.5.12 and 3.6.x before 3.6.9, Thunderbird before 3.0.7 and 3.1.x before 3.1.3, and SeaMonkey before 2.0.7 might allow remote attackers to execute arbitrary code via a bidirectional text run.
A9: CVE-2010-3168 | B9: Mozilla Firefox before 3.5.12 and 3.6.x before 3.6.9, Thunderbird before 3.0.7 and 3.1.x before 3.1.3, and SeaMonkey before 2.0.7 do not properly restrict the role of property changes in triggering XUL tree removal, which allows remote attackers to cause a denial of service (deleted memory access and application crash) or possibly execute arbitrary code by setting unspecified properties.
A10: CVE-2010-3778 | B10: Unspecified vulnerability in Mozilla Firefox 3.5.x before 3.5.16, Thunderbird before 3.0.11, and SeaMonkey before 2.0.11 allows remote attackers to cause a denial of service (memory corruption and application crash) or possibly execute arbitrary code via unknown vectors.
A11: CVE-2011-0054 | B11: Buffer overflow in the JavaScript engine in Mozilla Firefox before 3.5.17 and 3.6.x before 3.6.14, and SeaMonkey before 2.0.12, might allow remote attackers to execute arbitrary code via vectors involving non-local JavaScript variables, aka an "upvarMap" issue.
A12: CVE-2011-0061 | B12: Buffer overflow in Mozilla Firefox 3.6.x before 3.6.14, Thunderbird before 3.1.8, and SeaMonkey before 2.0.12 might allow remote attackers to execute arbitrary code or cause a denial of service (application crash) via a crafted JPEG image.
... A164: CVE-2014-4021 | B164: Xen 3.2.x through 4.4.x does not properly clean memory pages recovered from guests, which allows local guest OS users to obtain sensitive information via unspecified vectors.
